<?xml version="1.0" ?>
<robot name="robot_vacuum" xmlns:xacro="http://www.ros.org/wiki/xacro">

<xacro:include filename="$(find robot_vacuum_description)/urdf/materials.xacro" />
<xacro:include filename="$(find robot_vacuum_description)/urdf/robot_vacuum.trans" />
<xacro:include filename="$(find robot_vacuum_description)/urdf/robot_vacuum.gazebo" />
<link name="base_link">
  <inertial>
    <origin xyz="-0.00400604735627117 0.0 0.06640790783033473" rpy="0 0 0"/>
    <mass value="43.841758375387045"/>
    <inertia ixx="0.285207" iyy="0.289631" izz="0.53281" ixy="-0.0" iyz="0.0" ixz="-0.006834"/>
  </inertial>
  <visual>
    <origin xyz="0 0 0" rpy="0 0 0"/>
    <geometry>
      <mesh filename="package://robot_vacuum_description/meshes/base_link.stl" scale="0.001 0.001 0.001"/>
    </geometry>
    <material name="silver"/>
  </visual>
  <collision>
    <origin xyz="0 0 0" rpy="0 0 0"/>
    <geometry>
      <mesh filename="package://robot_vacuum_description/meshes/base_link.stl" scale="0.001 0.001 0.001"/>
    </geometry>
  </collision>
</link>

<link name="LeftWheel_1">
  <inertial>
    <origin xyz="0.0 -0.02325000000000002 0.0" rpy="0 0 0"/>
    <mass value="0.931455694966405"/>
    <inertia ixx="0.000357" iyy="0.000378" izz="0.000357" ixy="-0.0" iyz="-0.0" ixz="0.0"/>
  </inertial>
  <visual>
    <origin xyz="-0.06 -0.1 -0.0285" rpy="0 0 0"/>
    <geometry>
      <mesh filename="package://robot_vacuum_description/meshes/LeftWheel_1.stl" scale="0.001 0.001 0.001"/>
    </geometry>
    <material name="silver"/>
  </visual>
  <collision>
    <origin xyz="-0.06 -0.1 -0.0285" rpy="0 0 0"/>
    <geometry>
      <mesh filename="package://robot_vacuum_description/meshes/LeftWheel_1.stl" scale="0.001 0.001 0.001"/>
    </geometry>
  </collision>
</link>

<link name="RightWheel_1">
  <inertial>
    <origin xyz="1.3877787807814457e-17 0.023249999999999993 -3.469446951953614e-18" rpy="0 0 0"/>
    <mass value="0.9314556949664043"/>
    <inertia ixx="0.000357" iyy="0.000378" izz="0.000357" ixy="-0.0" iyz="0.0" ixz="0.0"/>
  </inertial>
  <visual>
    <origin xyz="-0.06 0.1 -0.0285" rpy="0 0 0"/>
    <geometry>
      <mesh filename="package://robot_vacuum_description/meshes/RightWheel_1.stl" scale="0.001 0.001 0.001"/>
    </geometry>
    <material name="silver"/>
  </visual>
  <collision>
    <origin xyz="-0.06 0.1 -0.0285" rpy="0 0 0"/>
    <geometry>
      <mesh filename="package://robot_vacuum_description/meshes/RightWheel_1.stl" scale="0.001 0.001 0.001"/>
    </geometry>
  </collision>
</link>

<link name="Lidar_1">
  <inertial>
    <origin xyz="0.0 4.615300017314898e-18 0.008999999999999994" rpy="0 0 0"/>
    <mass value="0.48341476868598726"/>
    <inertia ixx="0.000145" iyy="0.000145" izz="0.000263" ixy="0.0" iyz="0.0" ixz="0.0"/>
  </inertial>
  <visual>
    <origin xyz="-0.09 -0.0 -0.1095" rpy="0 0 0"/>
    <geometry>
      <mesh filename="package://robot_vacuum_description/meshes/Lidar_1.stl" scale="0.001 0.001 0.001"/>
    </geometry>
    <material name="silver"/>
  </visual>
  <collision>
    <origin xyz="-0.09 -0.0 -0.1095" rpy="0 0 0"/>
    <geometry>
      <mesh filename="package://robot_vacuum_description/meshes/Lidar_1.stl" scale="0.001 0.001 0.001"/>
    </geometry>
  </collision>
</link>

<link name="Camera_1">
  <inertial>
    <origin xyz="-4.066178605979798e-05 1.2954973832761082e-17 0.008000000000000007" rpy="0 0 0"/>
    <mass value="0.013454679038050983"/>
    <inertia ixx="0.0" iyy="0.0" izz="0.0" ixy="-0.0" iyz="0.0" ixz="0.0"/>
  </inertial>
  <visual>
    <origin xyz="-0.1575 -0.0 -0.066" rpy="0 0 0"/>
    <geometry>
      <mesh filename="package://robot_vacuum_description/meshes/Camera_1.stl" scale="0.001 0.001 0.001"/>
    </geometry>
    <material name="silver"/>
  </visual>
  <collision>
    <origin xyz="-0.1575 -0.0 -0.066" rpy="0 0 0"/>
    <geometry>
      <mesh filename="package://robot_vacuum_description/meshes/Camera_1.stl" scale="0.001 0.001 0.001"/>
    </geometry>
  </collision>
</link>

<joint name="Revolute1" type="continuous">
  <origin xyz="0.06 0.1 0.0285" rpy="0 0 0"/>
  <parent link="base_link"/>
  <child link="LeftWheel_1"/>
  <axis xyz="0.0 1.0 0.0"/>
</joint>

<joint name="Revolute2" type="continuous">
  <origin xyz="0.06 -0.1 0.0285" rpy="0 0 0"/>
  <parent link="base_link"/>
  <child link="RightWheel_1"/>
  <axis xyz="0.0 1.0 0.0"/>
</joint>

<joint name="Rigid1" type="fixed">
  <origin xyz="0.09 0.0 0.1095" rpy="0 0 0"/>
  <parent link="base_link"/>
  <child link="Lidar_1"/>
</joint>

<joint name="Rigid2" type="fixed">
  <origin xyz="0.1575 0.0 0.066" rpy="0 0 0"/>
  <parent link="base_link"/>
  <child link="Camera_1"/>
</joint>

</robot>
